Workbook

Sheet Hoja1
A1: Fecha | B1: Mes | C1: Id Pedido | D1: Canal | E1: Vendedor | F1: Pago | G1: Producto | H1: Categoría | I1: Precio Unit | J1: Cantidad | K1: Total
A2: 46023 | B2: =TEXT(Tabla5[[#This Row],[Fecha]],"MMMM") -> enero | C2: 1000 | D2: mostrador | E2: Juan Perez | F2: Efectivo | G2: Porción Muzza | H2: =VLOOKUP(G2, Listas!G:H, 2, FALSE) -> Pizza | I2: =VLOOKUP(G2, Listas!G:I, 3, FALSE) -> 2800 | J2: 2 | K2: =I2*J2 -> 5600
A3: 46024 | B3: =TEXT(Tabla5[[#This Row],[Fecha]],"MMMM") -> enero | C3: 1001 | D3: salón | E3: Luciano Alvarez | F3: Tarjeta | G3: Grande de Fugazzeta | H3: =VLOOKUP(G3, Listas!G:H, 2, FALSE) -> Pizza | I3: =VLOOKUP(G3, Listas!G:I, 3, FALSE) -> 21000 | J3: 1 | K3: =I3*J3 -> 21000 | S3: selecciona el mes: | W3: Cantidad de pedidos realizados
A4: 46025 | B4: =TEXT(Tabla5[[#This Row],[Fecha]],"MMMM") -> enero | C4: 1002 | D4: Delivery | E4: Mateo Perez | F4: QR | G4: Agua Mineral | H4: =VLOOKUP(G4, Listas!G:H, 2, FALSE) -> Bebidas | I4: =VLOOKUP(G4, Listas!G:I, 3, FALSE) -> 1800 | J4: 3 | K4: =I4*J4 -> 5400 | S4: Enero | W4: =COUNTIFS(Tabla5[Mes], $S$4) -> 31
A5: 46026 | B5: =TEXT(Tabla5[[#This Row],[Fecha]],"MMMM") -> enero | C5: 1003 | D5: Delivery | E5: Sol Solis | F5: Efectivo | G5: Gaseosa 500ml | H5: =VLOOKUP(G5, Listas!G:H, 2, FALSE) -> Bebidas | I5: =VLOOKUP(G5, Listas!G:I, 3, FALSE) -> 2500 | J5: 1 | K5: =I5*J5 -> 2500
A6: 46027 | B6: =TEXT(Tabla5[[#This Row],[Fecha]],"MMMM") -> enero | C6: 1004 | D6: mostrador | E6: Santiago Lopez | F6: tarjeta | G6: Fainá con Verdeo | H6: =VLOOKUP(G6, Listas!G:H, 2, FALSE) -> Acompañamientos | I6: =VLOOKUP(G6, Listas!G:I, 3, FALSE) -> 2400 | J6: 2 | K6: =I6*J6 -> 4800 | S6: Facturacion | W6: Facturacion Total | AA6: Facturacion Promedio
A7: 46028 | B7: =TEXT(Tabla5[[#This Row],[Fecha]],"MMMM") -> enero | C7: 1005 | D7: salón | E7: Juan Perez | F7: Efectivo | G7: Porción Muzza | H7: =VLOOKUP(G7, Listas!G:H, 2, FALSE) -> Pizza | I7: =VLOOKUP(G7, Listas!G:I, 3, FALSE) -> 2800 | J7: 5 | K7: =I7*J7 -> 14000 | S7: =SUMIFS(Tabla5[Total],Tabla5[Mes],$S$4) -> 638400 | W7: =SUM(Tabla5[Total]) -> 2508800 | AA7: =AVERAGEIFS(Tabla5[Total],Tabla5[Mes],$S$4) -> 20593.548
A8: 46029 | B8: =TEXT(Tabla5[[#This Row],[Fecha]],"MMMM") -> enero | C8: 1006 | D8: mostrador | E8: Luciano Alvarez | F8: QR | G8: Gaseosa 500ml | H8: =VLOOKUP(G8, Listas!G:H, 2, FALSE) -> Bebidas | I8: =VLOOKUP(G8, Listas!G:I, 3, FALSE) -> 2500 | J8: 2 | K8: =I8*J8 -> 5000
A9: 46030 | B9: =TEXT(Tabla5[[#This Row],[Fecha]],"MMMM") -> enero | C9: 1007 | D9: Delivery | E9: Mateo Perez | F9: Tarjeta | G9: Pizza Calabresa | H9: =VLOOKUP(G9, Listas!G:H, 2, FALSE) -> Pizza | I9: =VLOOKUP(G9, Listas!G:I, 3, FALSE) -> 20000 | J9: 1 | K9: =I9*J9 -> 20000 | S9: Resumen de Facturacion | W9: Eficiencia por Vendedor | AA9: Ranking de Canales y Pagos | AG9: Resumen de Facturacion
A10: 46031 | B10: =TEXT(Tabla5[[#This Row],[Fecha]],"MMMM") -> enero | C10: 1008 | D10: mostrador | E10: Sol Solis | F10: QR | G10: Grande de Muzza | H10: =VLOOKUP(G10, Listas!G:H, 2, FALSE) -> Pizza | I10: =VLOOKUP(G10, Listas!G:I, 3, FALSE) -> 18000 | J10: 2 | K10: =I10*J10 -> 36000 | S10: Categoria | T10: cantidades | U10: Monto | W10: Vendedor | X10: ventas totales | Y10: Cantidad de Pedidos | AA10: Canal | AB10: Efectivo | AC10: Tarjeta | AD10: QR | AE10: Total | AG10: Meses | AH10: Facturación Mensual
A11: 46032 | B11: =TEXT(Tabla5[[#This Row],[Fecha]],"MMMM") -> enero | C11: 1009 | D11: mostrador | E11: Santiago Lopez | F11: Efectivo | G11: Porción Napolitana | H11: =VLOOKUP(G11, Listas!G:H, 2, FALSE) -> Pizza | I11: =VLOOKUP(G11, Listas!G:I, 3, FALSE) -> 3000 | J11: 4 | K11: =I11*J11 -> 12000 | S11: {=_xlfn.UNIQUE(Tabla5[Categoría])} -> Pizza | T11: =SUMIFS(Tabla5[Cantidad], Tabla5[Mes], $S$4, Tabla5[Categoría], "Pizza") -> 39 | U11: =SUMIFS(Tabla5[Total], Tabla5[Mes], $S$4, Tabla5[Categoría], "Pizza") -> 539000 | W11: {=_xlfn.UNIQUE(Tabla5[Vendedor])} -> Juan Perez | X11: =SUMIFS(Tabla5[Total], Tabla5[Mes], $S$4) -> 638400 | Y11: =COUNTIFS(Tabla5[Mes], $S$4, Tabla5[Vendedor], "Juan Perez") -> 7 | AA11: {=_xlfn.UNIQUE(Tabla5[Canal])} -> mostrador | AB11: =SUMIFS(Tabla5[Total], Tabla5[Mes], $S$4, Tabla5[Canal], "Mostrador", Tabla5[Pago], "Efectivo") -> 99600 | AC11: =SUMIFS(Tabla5[Total], Tabla5[Mes], $S$4, Tabla5[Canal], "Mostrador", Tabla5[Pago], "Tarjeta") -> 101700 | AD11: =SUMIFS(Tabla5[Total], Tabla5[Mes], $S$4, Tabla5[Canal], "Mostrador", Tabla5[Pago], "QR") -> 70000 | AE11: =SUM(AB11 +AC11 +AD11) -> 271300 | AG11: Enero | AH11: =SUMIF(Tabla5[Mes], "enero", Tabla5[Total]) -> 638400
A12: 46033 | B12: =TEXT(Tabla5[[#This Row],[Fecha]],"MMMM") -> enero | C12: 1010 | D12: mostrador | E12: Juan Perez | F12: QR | G12: Gaseosa 500ml | H12: =VLOOKUP(G12, Listas!G:H, 2, FALSE) -> Bebidas | I12: =VLOOKUP(G12, Listas!G:I, 3, FALSE) -> 2500 | J12: 2 | K12: =I12*J12 -> 5000 | S12: Bebidas | T12: =SUMIFS(Tabla5[Cantidad], Tabla5[Mes], $S$4, Tabla5[Categoría], "Bebidas") -> 20 | U12: =SUMIFS(Tabla5[Total], Tabla5[Mes], $S$4, Tabla5[Categoría], "Bebidas") -> 61800 | W12: Luciano Alvarez | X12: =SUMIFS(Tabla5[Total], Tabla5[Mes], $S$4, Tabla5[Vendedor], "Luciano Alvarez") -> 221500 | Y12: =COUNTIFS(Tabla5[Mes], $S$4, Tabla5[Vendedor], "Luciano Alvarez") -> 6 | AA12: salón | AB12: =SUMIFS(Tabla5[Total], Tabla5[Mes], $S$4, Tabla5[Canal], "Salón", Tabla5[Pago], "Efectivo") -> 71300 | AC12: =SUMIFS(Tabla5[Total], Tabla5[Mes], $S$4, Tabla5[Canal], "Salón", Tabla5[Pago], "Tarjeta") -> 131000 | AD12: =SUMIFS(Tabla5[Total], Tabla5[Mes], $S$4, Tabla5[Canal], "Salón", Tabla5[Pago], "QR") -> 0 | AE12: =SUM(AB12 +AC12 +AD12) -> 202300 | AG12: Febrero | AH12: =SUMIF(Tabla5[Mes], "Febrero", Tabla5[Total]) -> 565200
A13: 46034 | B13: =TEXT(Tabla5[[#This Row],[Fecha]],"MMMM") -> enero | C13: 1011 | D13: mostrador | E13: Luciano Alvarez | F13: Tarjeta | G13: Tiramisú | H13: =VLOOKUP(G13, Listas!G:H, 2, FALSE) -> Postres | I13: =VLOOKUP(G13, Listas!G:I, 3, FALSE) -> 5500 | J13: 1 | K13: =I13*J13 -> 5500 | S13: Acompañamientos | T13: =SUMIFS(Tabla5[Cantidad], Tabla5[Mes], $S$4, Tabla5[Categoría], "Acompañamientos") -> 10 | U13: =SUMIFS(Tabla5[Total], Tabla5[Mes], $S$4, Tabla5[Categoría], "Acompañamientos") -> 21600 | W13: Mateo Perez | X13: =SUMIFS(Tabla5[Total], Tabla5[Mes], $S$4, Tabla5[Vendedor], "Mateo Perez") -> 83800 | Y13: =COUNTIFS(Tabla5[Mes], $S$4, Tabla5[Vendedor], "Mateo Perez") -> 6 | AA13: Delivery | AB13: =SUMIFS(Tabla5[Total], Tabla5[Mes], $S$4, Tabla5[Canal], "Delivery", Tabla5[Pago], "Efectivo") -> 60400 | AC13: =SUMIFS(Tabla5[Total], Tabla5[Mes], $S$4, Tabla5[Canal], "Delivery", Tabla5[Pago], "Tarjeta") -> 92000 | AD13: =SUMIFS(Tabla5[Total], Tabla5[Mes], $S$4, Tabla5[Canal], "Delivery", Tabla5[Pago], "QR") -> 12400 | AE13: =SUM(AB13 +AC13 +AD13) -> 164800 | AG13: Marzo | AH13: =SUMIF(Tabla5[Mes], "Marzo", Tabla5[Total]) -> 681400
A14: 46035 | B14: =TEXT(Tabla5[[#This Row],[Fecha]],"MMMM") -> enero | C14: 1012 | D14: salón | E14: Mateo Perez | F14: Efectivo | G14: Cerveza Quilmes 1L | H14: =VLOOKUP(G14, Listas!G:H, 2, FALSE) -> Bebidas | I14: =VLOOKUP(G14, Listas!G:I, 3, FALSE) -> 4500 | J14: 1 | K14: =I14*J14 -> 4500 | S14: Postres | T14: =SUMIFS(Tabla5[Cantidad], Tabla5[Mes], $S$4, Tabla5[Categoría], "Postres") -> 4 | U14: =SUMIFS(Tabla5[Total], Tabla5[Mes], $S$4, Tabla5[Categoría], "Postres") -> 16000 | W14: Sol Solis | X14: =SUMIFS(Tabla5[Total], Tabla5[Mes], $S$4, Tabla5[Vendedor], "Sol Solis") -> 100700 | Y14: =COUNTIFS(Tabla5[Mes], $S$4, Tabla5[Vendedor], "Sol Solis") -> 6 | AG14: Abril | AH14: =SUMIF(Tabla5[Mes], "Abril", Tabla5[Total]) -> 623800
A15: 46036 | B15: =TEXT(Tabla5[[#This Row],[Fecha]],"MMMM") -> enero | C15: 1013 | D15: Delivery | E15: Sol Solis | F15: Efectivo | G15: Porción Muzza | H15: =VLOOKUP(G15, Listas!G:H, 2, FALSE) -> Pizza | I15: =VLOOKUP(G15, Listas!G:I, 3, FALSE) -> 2800 | J15: 3 | K15: =I15*J15 -> 8400 | W15: Santiago Lopez | X15: =SUMIFS(Tabla5[Total], Tabla5[Mes], $S$4, Tabla5[Vendedor], "Santiago Lopez") -> 101800 | Y15: =COUNTIFS(Tabla5[Mes], $S$4, Tabla5[Vendedor], "Santiago Lopez") -> 6 | AG15: Mayo | AH15: =SUMIF(Tabla5[Mes], "Mayo", Tabla5[Total]) -> 0
A16: 46037 | B16: =TEXT(Tabla5[[#This Row],[Fecha]],"MMMM") -> enero | C16: 1014 | D16: Delivery | E16: Santiago Lopez | F16: QR | G16: Cerveza Quilmes 1L | H16: =VLOOKUP(G16, Listas!G:H, 2, FALSE) -> Bebidas | I16: =VLOOKUP(G16, Listas!G:I, 3, FALSE) -> 4500 | J16: 1 | K16: =I16*J16 -> 4500 | AG16: Junio | AH16: =SUMIF(Tabla5[Mes], "Junio", Tabla5[Total]) -> 0
A17: 46038 | B17: =TEXT(Tabla5[[#This Row],[Fecha]],"MMMM") -> enero | C17: 1015 | D17: mostrador | E17: Juan Perez | F17: tarjeta | G17: Pizza Calabresa | H17: =VLOOKUP(G17, Listas!G:H, 2, FALSE) -> Pizza | I17: =VLOOKUP(G17, Listas!G:I, 3, FALSE) -> 20000 | J17: 4 | K17: =I17*J17 -> 80000 | AG17: Julio | AH17: =SUMIF(Tabla5[Mes], "Julio", Tabla5[Total]) -> 0
A18: 46039 | B18: =TEXT(Tabla5[[#This Row],[Fecha]],"MMMM") -> enero | C18: 1016 | D18: salón | E18: Luciano Alvarez | F18: tarjeta | G18: Pizza Jamón y Morrón | H18: =VLOOKUP(G18, Listas!G:H, 2, FALSE) -> Pizza | I18: =VLOOKUP(G18, Listas!G:I, 3, FALSE) -> 22000 | J18: 5 | K18: =I18*J18 -> 110000 | AG18: Agosto | AH18: =SUMIF(Tabla5[Mes], "Agosto", Tabla5[Total]) -> 0
A19: 46040 | B19: =TEXT(Tabla5[[#This Row],[Fecha]],"MMMM") -> enero | C19: 1017 | D19: mostrador | E19: Mateo Perez | F19: QR | G19: Cerveza Quilmes 1L | H19: =VLOOKUP(G19, Listas!G:H, 2, FALSE) -> Bebidas | I19: =VLOOKUP(G19, Listas!G:I, 3, FALSE) -> 4500 | J19: 1 | K19: =I19*J19 -> 4500 | AG19: Septiembre | AH19: =SUMIF(Tabla5[Mes], "Septiembre", Tabla5[Total]) -> 0
A20: 46041 | B20: =TEXT(Tabla5[[#This Row],[Fecha]],"MMMM") -> enero | C20: 1018 | D20: Delivery | E20: Sol Solis | F20: Efectivo | G20: Grande de Muzza | H20: =VLOOKUP(G20, Listas!G:H, 2, FALSE) -> Pizza | I20: =VLOOKUP(G20, Listas!G:I, 3, FALSE) -> 18000 | J20: 2 | K20: =I20*J20 -> 36000 | AG20: Octubre | AH20: =SUMIF(Tabla5[Mes], "Octubre", Tabla5[Total]) -> 0
A21: 46042 | B21: =TEXT(Tabla5[[#This Row],[Fecha]],"MMMM") -> enero | C21: 1019 | D21: mostrador | E21: Santiago Lopez | F21: Tarjeta | G21: Fainá clásica | H21: =VLOOKUP(G21, Listas!G:H, 2, FALSE) -> Acompañamientos | I21: =VLOOKUP(G21, Listas!G:I, 3, FALSE) -> 2000 | J21: 3 | K21: =I21*J21 -> 6000 | AG21: Noviembre | AH21: =SUMIF(Tabla5[Mes], "Noviembre", Tabla5[Total]) -> 0
A22: 46043 | B22: =TEXT(Tabla5[[#This Row],[Fecha]],"MMMM") -> enero | C22: 1020 | D22: mostrador | E22: Juan Perez | F22: QR | G22: Flan con dulce de leche | H22: =VLOOKUP(G22, Listas!G:H, 2, FALSE) -> Postres | I22: =VLOOKUP(G22, Listas!G:I, 3, FALSE) -> 3500 | J22: 3 | K22: =I22*J22 -> 10500 | AG22: Diciembre | AH22: =SUMIF(Tabla5[Mes], "Diciembre", Tabla5[Total]) -> 0
A23: 46044 | B23: =TEXT(Tabla5[[#This Row],[Fecha]],"MMMM") -> enero | C23: 1021 | D23: mostrador | E23: Luciano Alvarez | F23: Efectivo | G23: Pizza Calabresa | H23: =VLOOKUP(G23, Listas!G:H, 2, FALSE) -> Pizza | I23: =VLOOKUP(G23, Listas!G:I, 3, FALSE) -> 20000 | J23: 1 | K23: =I23*J23 -> 20000
A24: 46045 | B24: =TEXT(Tabla5[[#This Row],[Fecha]],"MMMM") -> enero | C24: 1022 | D24: mostrador | E24: Mateo Perez | F24: Tarjeta | G24: Agua Mineral | H24: =VLOOKUP(G24, Listas!G:H, 2, FALSE) -> Bebidas | I24: =VLOOKUP(G24, Listas!G:I, 3, FALSE) -> 1800 | J24: 3 | K24: =I24*J24 -> 5400 | AG24: Cantidad de Productos vendidos
A25: 46046 | B25: =TEXT(Tabla5[[#This Row],[Fecha]],"MMMM") -> enero | C25: 1023 | D25: salón | E25: Sol Solis | F25: Efectivo | G25: Empanada de Carne | H25: =VLOOKUP(G25, Listas!G:H, 2, FALSE) -> Acompañamientos | I25: =VLOOKUP(G25, Listas!G:I, 3, FALSE) -> 2200 | J25: 4 | K25: =I25*J25 -> 8800 | AG25: Producto | AH25: Cantidad Vendida
A26: 46047 | B26: =TEXT(Tabla5[[#This Row],[Fecha]],"MMMM") -> enero | C26: 1024 | D26: Delivery | E26: Santiago Lopez | F26: QR | G26: Gaseosa 500ml | H26: =VLOOKUP(G26, Listas!G:H, 2, FALSE) -> Bebidas | I26: =VLOOKUP(G26, Listas!G:I, 3, FALSE) -> 2500 | J26: 1 | K26: =I26*J26 -> 2500 | AG26: Porción Muzza | AH26: =SUMIFS(Tabla5[Cantidad], Tabla5[Mes], $S$4, Tabla5[Producto], "Porción Muzza") -> 10
A27: 46048 | B27: =TEXT(Tabla5[[#This Row],[Fecha]],"MMMM") -> enero | C27: 1025 | D27: Delivery | E27: Juan Perez | F27: efectivo | G27: Cerveza Quilmes 1L | H27: =VLOOKUP(G27, Listas!G:H, 2, FALSE) -> Bebidas | I27: =VLOOKUP(G27, Listas!G:I, 3, FALSE) -> 4500 | J27: 3 | K27: =I27*J27 -> 13500 | AG27: Grande de Muzza | AH27: =SUMIFS(Tabla5[Cantidad], Tabla5[Mes], $S$4, Tabla5[Producto], "Grande de Muzza") -> 8
A28: 46049 | B28: =TEXT(Tabla5[[#This Row],[Fecha]],"MMMM") -> enero | C28: 1026 | D28: mostrador | E28: Luciano Alvarez | F28: Efectivo | G28: Pizza Calabresa | H28: =VLOOKUP(G28, Listas!G:H, 2, FALSE) -> Pizza | I28: =VLOOKUP(G28, Listas!G:I, 3, FALSE) -> 20000 | J28: 3 | K28: =I28*J28 -> 60000 | AG28: Grande de Fugazzeta | AH28: =SUMIFS(Tabla5[Cantidad], Tabla5[Mes], $S$4, Tabla5[Producto], "Grande de Fugazzeta") -> 1
A29: 46050 | B29: =TEXT(Tabla5[[#This Row],[Fecha]],"MMMM") -> enero | C29: 1027 | D29: salón | E29: Mateo Perez | F29: Efectivo | G29: Pizza Jamón y Morrón | H29: =VLOOKUP(G29, Listas!G:H, 2, FALSE) -> Pizza | I29: =VLOOKUP(G29, Listas!G:I, 3, FALSE) -> 22000 | J29: 2 | K29: =I29*J29 -> 44000 | AG29: Porción Napolitana | AH29: =SUMIFS(Tabla5[Cantidad], Tabla5[Mes], $S$4, Tabla5[Producto], "Porción Napolitana") -> 4
A30: 46051 | B30: =TEXT(Tabla5[[#This Row],[Fecha]],"MMMM") -> enero | C30: 1028 | D30: mostrador | E30: Sol Solis | F30: QR | G30: Cerveza Quilmes 1L | H30: =VLOOKUP(G30, Listas!G:H, 2, FALSE) -> Bebidas | I30: =VLOOKUP(G30, Listas!G:I, 3, FALSE) -> 4500 | J30: 2 | K30: =I30*J30 -> 9000 | AG30: Pizza Calabresa | AH30: =SUMIFS(Tabla5[Cantidad], Tabla5[Mes], $S$4, Tabla5[Producto], "Pizza Calabresa") -> 9
A31: 46052 | B31: =TEXT(Tabla5[[#This Row],[Fecha]],"MMMM") -> enero | C31: 1029 | D31: Delivery | E31: Santiago Lopez | F31: Tarjeta | G31: Grande de Muzza | H31: =VLOOKUP(G31, Listas!G:H, 2, FALSE) -> Pizza | I31: =VLOOKUP(G31, Listas!G:I, 3, FALSE) -> 18000 | J31: 4 | K31: =I31*J31 -> 72000 | AG31: Pizza Jamón y Morrón | AH31: =SUMIFS(Tabla5[Cantidad], Tabla5[Mes], $S$4, Tabla5[Producto], "Pizza Jamón y Morrón") -> 7
A32: 46053 | B32: =TEXT(Tabla5[[#This Row],[Fecha]],"MMMM") -> enero | C32: 1030 | D32: mostrador | E32: Juan Perez | F32: Efectivo | G32: Fainá clásica | H32: =VLOOKUP(G32, Listas!G:H, 2, FALSE) -> Acompañamientos | I32: =VLOOKUP(G32, Listas!G:I, 3, FALSE) -> 2000 | J32: 1 | K32: =I32*J32 -> 2000 | AG32: Fainá clásica | AH32: =SUMIFS(Tabla5[Cantidad], Tabla5[Mes], $S$4, Tabla5[Producto], "Fainá clásica") -> 4
A33: 46054 | B33: =TEXT(Tabla5[[#This Row],[Fecha]],"MMMM") -> febrero | C33: 1031 | D33: mostrador | E33: Luciano Alvarez | F33: Efectivo | G33: Flan con dulce de leche | H33: =VLOOKUP(G33, Listas!G:H, 2, FALSE) -> Postres | I33: =VLOOKUP(G33, Listas!G:I, 3, FALSE) -> 3500 | J33: 2 | K33: =I33*J33 -> 7000 | AG33: Fainá con Verdeo | AH33: =SUMIFS(Tabla5[Cantidad], Tabla5[Mes], $S$4, Tabla5[Producto], "Fainá con Verdeo") -> 2
A34: 46055 | B34: =TEXT(Tabla5[[#This Row],[Fecha]],"MMMM") -> febrero | C34: 1032 | D34: mostrador | E34: Mateo Perez | F34: QR | G34: Pizza Calabresa | H34: =VLOOKUP(G34, Listas!G:H, 2, FALSE) -> Pizza | I34: =VLOOKUP(G34, Listas!G:I, 3, FALSE) -> 20000 | J34: 3 | K34: =I34*J34 -> 60000 | AG34: Empanada de Carne | AH34: =SUMIFS(Tabla5[Cantidad], Tabla5[Mes], $S$4, Tabla5[Producto], "Empanada de Carne") -> 4
A35: 46056 | B35: =TEXT(Tabla5[[#This Row],[Fecha]],"MMMM") -> febrero | C35: 1033 | D35: mostrador | E35: Sol Solis | F35: tarjeta | G35: Agua Mineral | H35: =VLOOKUP(G35, Listas!G:H, 2, FALSE) -> Bebidas | I35: =VLOOKUP(G35, Listas!G:I, 3, FALSE) -> 1800 | J35: 2 | K35: =I35*J35 -> 3600 | AG35: Empanada de Jamón y Queso | AH35: =SUMIFS(Tabla5[Cantidad], Tabla5[Mes], $S$4, Tabla5[Producto], "Empanada de Jamón y Queso") -> 0
A36: 46057 | B36: =TEXT(Tabla5[[#This Row],[Fecha]],"MMMM") -> febrero | C36: 1034 | D36: salón | E36: Santiago Lopez | F36: tarjeta | G36: Empanada de Carne | H36: =VLOOKUP(G36, Listas!G:H, 2, FALSE) -> Acompañamientos | I36: =VLOOKUP(G36, Listas!G:I, 3, FALSE) -> 2200 | J36: 1 | K36: =I36*J36 -> 2200 | AG36: Gaseosa 500ml | AH36: =SUMIFS(Tabla5[Cantidad], Tabla5[Mes], $S$4, Tabla5[Producto], "Gaseosa 500ml") -> 6
A37: 46058 | B37: =TEXT(Tabla5[[#This Row],[Fecha]],"MMMM") -> febrero | C37: 1035 | D37: Delivery | E37: Juan Perez | F37: qr | G37: Gaseosa 500ml | H37: =VLOOKUP(G37, Listas!G:H, 2, FALSE) -> Bebidas | I37: =VLOOKUP(G37, Listas!G:I, 3, FALSE) -> 2500 | J37: 3 | K37: =I37*J37 -> 7500 | AG37: Cerveza Quilmes 1L | AH37: =SUMIFS(Tabla5[Cantidad], Tabla5[Mes], $S$4, Tabla5[Producto], "Cerveza Quilmes 1L") -> 8
A38: 46059 | B38: =TEXT(Tabla5[[#This Row],[Fecha]],"MMMM") -> febrero | C38: 1036 | D38: Delivery | E38: Luciano Alvarez | F38: Efectivo | G38: Cerveza Quilmes 1L | H38: =VLOOKUP(G38, Listas!G:H, 2, FALSE) -> Bebidas | I38: =VLOOKUP(G38, Listas!G:I, 3, FALSE) -> 4500 | J38: 2 | K38: =I38*J38 -> 9000 | AG38: Agua Mineral | AH38: =SUMIFS(Tabla5[Cantidad], Tabla5[Mes], $S$4, Tabla5[Producto], "Agua Mineral") -> 6
A39: 46060 | B39: =TEXT(Tabla5[[#This Row],[Fecha]],"MMMM") -> febrero | C39: 1037 | D39: mostrador | E39: Mateo Perez | F39: Tarjeta | G39: Pizza Calabresa | H39: =VLOOKUP(G39, Listas!G:H, 2, FALSE) -> Pizza | I39: =VLOOKUP(G39, Listas!G:I, 3, FALSE) -> 20000 | J39: 5 | K39: =I39*J39 -> 100000 | AG39: Vino de la casa | AH39: =SUMIFS(Tabla5[Cantidad], Tabla5[Mes], $S$4, Tabla5[Producto], "Vino de la casa") -> 0
A40: 46061 | B40: =TEXT(Tabla5[[#This Row],[Fecha]],"MMMM") -> febrero | C40: 1038 | D40: salón | E40: Sol Solis | F40: QR | G40: Pizza Jamón y Morrón | H40: =VLOOKUP(G40, Listas!G:H, 2, FALSE) -> Pizza | I40: =VLOOKUP(G40, Listas!G:I, 3, FALSE) -> 22000 | J40: 2 | K40: =I40*J40 -> 44000 | AG40: Flan con dulce de leche | AH40: =SUMIFS(Tabla5[Cantidad], Tabla5[Mes], $S$4, Tabla5[Producto], "Flan con dulce de leche") -> 3
...

Sheet Listas
G1: Producto | H1: Categoria | I1: Precio | L1: Meses
G2: Porción Muzza | H2: Pizza | I2: 2800 | L2: Enero
C3: Canal | E3: pago | G3: Grande de Muzza | H3: Pizza | I3: 18000 | L3: Febrero
C4: mostrador | E4: efectivo | G4: Grande de Fugazzeta | H4: Pizza | I4: 21000 | L4: Marzo
C5: salón | E5: tarjeta | G5: Porción Napolitana | H5: Pizza | I5: 3000 | L5: Abril
C6: Delivery | E6: QR | G6: Pizza Calabresa | H6: Pizza | I6: 20000 | L6: Mayo
G7: Pizza Jamón y Morrón | H7: Pizza | I7: 22000 | L7: Junio | P7: Resumen de Facturacion | S7: Etiquetas de fila | T7: Promedio de Precio Unit | X7: Producto | Y7: Cantidad Vendida
G8: Fainá clásica | H8: Acompañamientos | I8: 2000 | L8: Julio | P8: Meses | Q8: Facturación Mensual | S8: Luciano Alvarez | T8: 9480.9524 | X8: Porción Muzza | Y8: =SUMIFS(Tabla5[Cantidad], Tabla5[Mes], $S$4, Tabla5[Producto], "Nombre del Producto") -> 0
G9: Fainá con Verdeo | H9: Acompañamientos | I9: 2400 | L9: Agosto | P9: Enero | Q9: =SUMIF(Tabla5[Mes], "enero", Tabla5[Total]) -> 638400 | S9: Sol Solis | T9: 8827.2727 | X9: Grande de Muzza | Y9: =SUMIFS(Tabla5[Cantidad], Tabla5[Mes], $S$4, Tabla5[Producto], "Grande de Muzza") -> 0
G10: Empanada de Carne | H10: Acompañamientos | I10: 2200 | L10: Septiembre | P10: Febrero | Q10: =SUMIF(Tabla5[Mes], "Febrero", Tabla5[Total]) -> 565200 | S10: Mateo Perez | T10: 8717.3913 | X10: Grande de Fugazzeta
G11: Empanada de Jamón y Queso | H11: Acompañamientos | I11: 2200 | L11: Octubre | P11: Marzo | Q11: =SUMIF(Tabla5[Mes], "Marzo", Tabla5[Total]) -> 681400 | S11: Santiago Lopez | T11: 7190.9091 | X11: Porción Napolitana
G12: Gaseosa 500ml | H12: Bebidas | I12: 2500 | L12: Noviembre | P12: Abril | Q12: =SUMIF(Tabla5[Mes], "Abril", Tabla5[Total]) -> 623800 | S12: Juan Perez | T12: 6554.5455 | X12: Pizza Calabresa
G13: Cerveza Quilmes 1L | H13: Bebidas | I13: 4500 | L13: Diciembre | P13: Mayo | Q13: =SUMIF(Tabla5[Mes], "Mayo", Tabla5[Total]) -> 0 | S13: Total general | T13: 8147.2727 | X13: Pizza Jamón y Morrón
G14: Agua Mineral | H14: Bebidas | I14: 1800 | P14: Junio | Q14: =SUMIF(Tabla5[Mes], "Junio", Tabla5[Total]) -> 0 | X14: Fainá clásica
G15: Vino de la casa | H15: Bebidas | I15: 8000 | P15: Julio | Q15: =SUMIF(Tabla5[Mes], "Julio", Tabla5[Total]) -> 0 | X15: Fainá con Verdeo
G16: Flan con dulce de leche | H16: Postres | I16: 3500 | P16: Agosto | Q16: =SUMIF(Tabla5[Mes], "Agosto", Tabla5[Total]) -> 0 | S16: Etiquetas de fila | T16: Promedio de Cantidad | X16: Empanada de Carne
G17: Budín de pan | H17: Postres | I17: 3500 | P17: Septiembre | Q17: =SUMIF(Tabla5[Mes], "Septiembre", Tabla5[Total]) -> 0 | S17: Porción Napolitana | T17: 4 | X17: Empanada de Jamón y Queso
G18: Tiramisú | H18: Postres | I18: 5500 | P18: Octubre | Q18: =SUMIF(Tabla5[Mes], "Octubre", Tabla5[Total]) -> 0 | S18: Porción Muzza | T18: 3.3333333 | X18: Gaseosa 500ml
G19: Porción de Queso y Dulce | H19: Postres | I19: 5000 | P19: Noviembre | Q19: =SUMIF(Tabla5[Mes], "Noviembre", Tabla5[Total]) -> 0 | S19: Pizza Jamón y Morrón | T19: 3 | X19: Cerveza Quilmes 1L
P20: Diciembre | Q20: =SUMIF(Tabla5[Mes], "Diciembre", Tabla5[Total]) -> 0 | S20: Grande de Fugazzeta | T20: 2.95 | X20: Agua Mineral
S21: Grande de Muzza | T21: 2.9428571 | X21: Vino de la casa
S22: Pizza Calabresa | T22: 2.8333333 | X22: Flan con dulce de leche
S23: Fainá con Verdeo | T23: 2.7 | X23: Budín de pan
S24: Agua Mineral | T24: 2.6666667 | X24: Tiramisú
S25: Empanada de Jamón y Queso | T25: 2.65 | X25: Porción de Queso y Dulce
S26: Empanada de Carne | T26: 2.5
S27: Gaseosa 500ml | T27: 2.1733333
S28: Cerveza Quilmes 1L | T28: 2
S29: Fainá clásica | T29: 2
S30: Flan con dulce de leche | T30: 1.9090909
S31: Tiramisú | T31: 1
S32: Total general | T32: 2.5654545
